[2023-02-18T11:57:58.910+0000] {taskinstance.py:1083} INFO - Dependencies all met for <TaskInstance: is459_t1.twitter_translator manual__2023-02-18T11:57:14.680966+00:00 [queued]>
[2023-02-18T11:57:58.927+0000] {taskinstance.py:1083} INFO - Dependencies all met for <TaskInstance: is459_t1.twitter_translator manual__2023-02-18T11:57:14.680966+00:00 [queued]>
[2023-02-18T11:57:58.928+0000] {taskinstance.py:1279} INFO - 
--------------------------------------------------------------------------------
[2023-02-18T11:57:58.929+0000] {taskinstance.py:1280} INFO - Starting attempt 1 of 3
[2023-02-18T11:57:58.930+0000] {taskinstance.py:1281} INFO - 
--------------------------------------------------------------------------------
[2023-02-18T11:57:58.964+0000] {taskinstance.py:1300} INFO - Executing <Task(PythonOperator): twitter_translator> on 2023-02-18 11:57:14.680966+00:00
[2023-02-18T11:57:58.973+0000] {standard_task_runner.py:55} INFO - Started process 225 to run task
[2023-02-18T11:57:58.977+0000] {standard_task_runner.py:82} INFO - Running: ['***', 'tasks', 'run', 'is459_t1', 'twitter_translator', 'manual__2023-02-18T11:57:14.680966+00:00', '--job-id', '35', '--raw', '--subdir', 'DAGS_FOLDER/is459t1_dag.py', '--cfg-path', '/tmp/tmpt3r4ruc5']
[2023-02-18T11:57:58.979+0000] {standard_task_runner.py:83} INFO - Job 35: Subtask twitter_translator
[2023-02-18T11:57:59.083+0000] {task_command.py:388} INFO - Running <TaskInstance: is459_t1.twitter_translator manual__2023-02-18T11:57:14.680966+00:00 [running]> on host 47e832255746
[2023-02-18T11:57:59.206+0000] {taskinstance.py:1507} INFO - Exporting the following env vars:
AIRFLOW_CTX_DAG_OWNER=lindy
AIRFLOW_CTX_DAG_ID=is459_t1
AIRFLOW_CTX_TASK_ID=twitter_translator
AIRFLOW_CTX_EXECUTION_DATE=2023-02-18T11:57:14.680966+00:00
AIRFLOW_CTX_TRY_NUMBER=1
AIRFLOW_CTX_DAG_RUN_ID=manual__2023-02-18T11:57:14.680966+00:00
[2023-02-18T11:58:55.648+0000] {taskinstance.py:1768} ERROR - Task failed with exception
Traceback (most recent call last):
  File "/home/airflow/.local/lib/python3.8/site-packages/airflow/operators/python.py", line 175, in execute
    return_value = self.execute_callable()
  File "/home/airflow/.local/lib/python3.8/site-packages/airflow/operators/python.py", line 192, in execute_callable
    return self.python_callable(*self.op_args, **self.op_kwargs)
  File "/opt/airflow/dags/twitter_translator.py", line 26, in run_translator
    df.at[i, 'Text'] = translator.translate(df.at[i, 'Text'], dest="en", src=df.at[i, 'Language']).text
  File "/home/airflow/.local/lib/python3.8/site-packages/googletrans/client.py", line 194, in translate
    data, response = self._translate(text, dest, src)
  File "/home/airflow/.local/lib/python3.8/site-packages/googletrans/client.py", line 122, in _translate
    if r.status_code != 200 and self.raise_Exception:
AttributeError: 'Translator' object has no attribute 'raise_Exception'
[2023-02-18T11:58:55.672+0000] {taskinstance.py:1318} INFO - Marking task as UP_FOR_RETRY. dag_id=is459_t1, task_id=twitter_translator, execution_date=20230218T115714, start_date=20230218T115758, end_date=20230218T115855
[2023-02-18T11:58:55.707+0000] {standard_task_runner.py:100} ERROR - Failed to execute job 35 for task twitter_translator ('Translator' object has no attribute 'raise_Exception'; 225)
[2023-02-18T11:58:55.730+0000] {local_task_job.py:208} INFO - Task exited with return code 1
[2023-02-18T11:58:55.767+0000] {taskinstance.py:2578} INFO - 0 downstream tasks scheduled from follow-on schedule check
